<! This file describes the snake environment. It is based on the swimmer and ant environments>

<mujoco model="snake">


  <compiler angle="degree" coordinate="local" inertiafromgeom="true"/>
  <option integrator="RK4" timestep="0.01"/>

  <default>
    <joint armature="0.1" damping="1" limited="true"/>
    <geom conaffinity="0" condim="3" density="30" friction="2 2 2" margin="0.01" rgba="0.208 0.82 0.208 0.5"/>
  </default>

  <asset>
    <texture builtin="gradient" height="100" rgb1="0.839 0.361 0.361" rgb2="1 1 1" type="skybox" width="100"/>
    <texture builtin="flat" height="1278" mark="cross" markrgb="1 1 1" name="texgeom" random="0.01" rgb1="0.8 0.6 0.4" rgb2="0.8 0.6 0.4" type="cube" width="127"/>
    <texture builtin="checker" height="100" name="texplane" rgb1="0.82 0.345 0.345" rgb2="1 1 1" type="2d" width="100"/>
    <material name="MatPlane" reflectance="0.5" shininess="1" specular="1" texrepeat="60 60" texture="texplane"/>
    <material name="geom" texture="texgeom" texuniform="true"/>
  </asset>


  <worldbody>
    <light cutoff="100" diffuse="1 1 1" dir="-0 0 -1.3" directional="true" exponent="1" pos="0 0 1.3" specular=".1 .1 .1"/>
    <geom conaffinity="1" condim="3" material="MatPlane" name="floor" pos="0 0 0" rgba="0.8 0.9 0.8 1" size="40 40 40" type="plane"/>

    <body name="aid_spbere" pos="0 0 0.45">
      <camera name="track" mode="trackcom" pos="0 -3 0.3" xyaxes="1 0 0 0 0 1"/>
      <geom name="aid_geom" pos="0 0 0" size="0.05" type="sphere"/>
      <joint armature="0" damping="0" limited="false" margin="0.01" name="root" pos="0 0 0" type="free"/>

      <body name="front_right_leg" pos="0 0 0">
        <geom fromto="0.0 0.0 0.0 -0.2 0 0.0" name="aux_2_geom" size="0.12" type="box"/>

        <body name="aux_2" pos="-0.2 0 0">
          <joint axis="0 1 0" name="hip_2" pos="0.0 0.0 0.0" range="-30 30" type="hinge"/>
          <geom fromto="0.0 0.0 0.0 -0.2 0 0.0" name="right_leg_geom" size="0.12" type="box"/>
          <body name="front_right_leg1" pos="0 0 0">
            <geom fromto="0.0 0.0 0.0 -0.2 0 0.0" name="aux_2_geom1" size="0.12" type="box"/>

            <body name="aux_21" pos="-0.2 0 0">
              <joint axis="0 1 0" name="hip_21" pos="0.0 0.0 0.0" range="-30 30" type="hinge"/>
              <geom fromto="0.0 0.0 0.0 -0.2 0 0.0" name="right_leg_geom1" size="0.12" type="box"/>


              <body name="front_right_leg2" pos="0 0 0">
                <geom fromto="0.0 0.0 0.0 -0.2 0 0.0" name="aux_2_geom2" size="0.12" type="box"/>

                <body name="aux_22" pos="-0.2 0 0">
                  <joint axis="0 1 0" name="hip_22" pos="0.0 0.0 0.0" range="-30 30" type="hinge"/>
                  <geom fromto="0.0 0.0 0.0 -0.2 0 0.0" name="right_leg_geom2" size="0.12" type="box"/>


                  <body name="front_right_leg3" pos="0 0 0">
                    <geom fromto="0.0 0.0 0.0 -0.2 0 0.0" name="aux_2_geom3" size="0.12" type="box"/>

                    <body name="aux_23" pos="-0.2 0 0">
                      <joint axis="0 1 0" name="hip_23" pos="0.0 0.0 0.0" range="-30 30" type="hinge"/>
                      <geom fromto="0.0 0.0 0.0 -0.2 0 0.0" name="right_leg_geom3" size="0.12" type="box"/>


                      <body name="front_right_leg4" pos="0 0 0">
                        <geom fromto="0.0 0.0 0.0 -0.2 0 0.0" name="aux_2_geom4" size="0.12" type="box"/>

                        <body name="aux_24" pos="-0.2 0 0">
                          <joint axis="0 1 0" name="hip_24" pos="0.0 0.0 0.0" range="-30 30" type="hinge"/>
                          <geom fromto="0.0 0.0 0.0 -0.2 0 0.0" name="right_leg_geom4" size="0.12" type="box"/>


                          <body name="front_right_leg5" pos="0 0 0">
                            <geom fromto="0.0 0.0 0.0 -0.2 0 0.0" name="aux_2_geom5" size="0.12" type="box"/>

                            <body name="aux_25" pos="-0.2 0 0">
                              <joint axis="0 1 0" name="hip_25" pos="0.0 0.0 0.0" range="-30 30" type="hinge"/>
                              <geom fromto="0.0 0.0 0.0 -0.2 0 0.0" name="right_leg_geom5" size="0.12" type="box"/>


                            </body>


                          </body>


                        </body>


                      </body>


                    </body>


                  </body>


                </body>
              </body>


            </body>

          </body>
        </body>

      </body>

      <body name="right_back_leg" pos="0 0 0">
        <geom fromto="0.0 0.0 0.0 0.2 0 0.0" name="aux_4_geom" size="0.12" type="box"/>

        <body name="aux_4" pos="0.2 0 0">
          <joint axis="0 1 0" name="hip_4" pos="0.0 0.0 0.0" range="-30 30" type="hinge"/>
          <geom fromto="0.0 0.0 0.0 0.2 0 0.0" name="rightback_leg_geom" size="0.12" type="box"/>


          <body name="right_back_leg1" pos="0 0 0">
            <geom fromto="0.0 0.0 0.0 0.2 0 0.0" name="aux_4_geom1" size="0.12" type="box"/>

            <body name="aux_41" pos="0.2 0 0">
              <joint axis="0 1 0" name="hip_41" pos="0.0 0.0 0.0" range="-30 30" type="hinge"/>
              <geom fromto="0.0 0.0 0.0 0.2 0 0.0" name="rightback_leg_geom1" size="0.12" type="box"/>


              <body name="right_back_leg2" pos="0 0 0">
                <geom fromto="0.0 0.0 0.0 0.2 0 0.0" name="aux_4_geom2" size="0.12" type="box"/>

                <body name="aux_42" pos="0.2 0 0">
                  <joint axis="0 1 0" name="hip_42" pos="0.0 0.0 0.0" range="-30 30" type="hinge"/>
                  <geom fromto="0.0 0.0 0.0 0.2 0 0.0" name="rightback_leg_geom2" size="0.12" type="box"/>


                  <body name="right_back_leg3" pos="0 0 0">
                    <geom fromto="0.0 0.0 0.0 0.2 0 0.0" name="aux_4_geom3" size="0.12" type="box"/>

                    <body name="aux_43" pos="0.2 0 0">
                      <joint axis="0 1 0" name="hip_43" pos="0.0 0.0 0.0" range="-30 30" type="hinge"/>
                      <geom fromto="0.0 0.0 0.0 0.2 0 0.0" name="rightback_leg_geom3" size="0.12" type="box"/>


                      <body name="right_back_leg4" pos="0 0 0">
                        <geom fromto="0.0 0.0 0.0 0.2 0 0.0" name="aux_4_geom4" size="0.12" type="box"/>

                        <body name="aux_44" pos="0.2 0 0">
                          <joint axis="0 1 0" name="hip_44" pos="0.0 0.0 0.0" range="-30 30" type="hinge"/>
                          <geom fromto="0.0 0.0 0.0 0.2 0 0.0" name="rightback_leg_geom4" size="0.12" type="box"/>


                          <body name="right_back_leg5" pos="0 0 0">
                            <geom fromto="0.0 0.0 0.0 0.2 0 0.0" name="aux_4_geom5" size="0.12" type="box"/>

                            <body name="aux_45" pos="0.2 0 0">
                              <joint axis="0 1 0" name="hip_45" pos="0.0 0.0 0.0" range="-30 30" type="hinge"/>
                              <geom fromto="0.0 0.0 0.0 0.2 0 0.0" name="rightback_leg_geom5" size="0.12" type="box"/>

                            </body>

                          </body>



                        </body>

                      </body>


                    </body>

                  </body>


                </body>

              </body>


            </body>

          </body>


        </body>

      </body>

    </body>

  </worldbody>


  <actuator>
    <motor ctrllimited="true" ctrlrange="-1.0 1.0" joint="hip_45" gear="150"/>
    <motor ctrllimited="true" ctrlrange="-1.0 1.0" joint="hip_44" gear="150"/>
    <motor ctrllimited="true" ctrlrange="-1.0 1.0" joint="hip_43" gear="150"/>
    <motor ctrllimited="true" ctrlrange="-1.0 1.0" joint="hip_42" gear="150"/>
    <motor ctrllimited="true" ctrlrange="-1.0 1.0" joint="hip_41" gear="150"/>
    <motor ctrllimited="true" ctrlrange="-1.0 1.0" joint="hip_4" gear="150"/>
    <motor ctrllimited="true" ctrlrange="-1.0 1.0" joint="hip_2" gear="150"/>
    <motor ctrllimited="true" ctrlrange="-1.0 1.0" joint="hip_21" gear="150"/>
    <motor ctrllimited="true" ctrlrange="-1.0 1.0" joint="hip_22" gear="150"/>
    <motor ctrllimited="true" ctrlrange="-1.0 1.0" joint="hip_23" gear="150"/>
    <motor ctrllimited="true" ctrlrange="-1.0 1.0" joint="hip_24" gear="150"/>
    <motor ctrllimited="true" ctrlrange="-1.0 1.0" joint="hip_25" gear="150"/>
  </actuator>


</mujoco>

